<?xml version="1.0"?>
<robot xmlns:xacro="http://www.ros.org/wiki/xacro" >

    <!-- Materials -->
    <material name="white">
        <color rgba="1 1 1 1" />
    </material>

    <material name="orange">
        <color rgba="1 0.3 0.1 1"/>
    </material>

    <material name="blue">
        <color rgba="0.2 0.2 1 1"/>
    </material>

    <material name="black">
        <color rgba="0 0 0 1"/>
    </material>

    <material name="yellow">
        <color rgba="1 1 0 1"/>
    </material>

    <!-- base (in middle of the two wheels) -->
    <link name="base_link">
        <origin xyz="0 0 0.033" />
    </link>

    <!-- CHASSIS (simplified body of the jvr-robot) -->

    <joint name="chassis_joint" type="fixed">
        <parent link="base_link"/>
        <child link="chassis"/>
        <origin xyz="-0.14 0 -0.015"/>
    </joint>

    <link name="chassis">
        <visual>
            <!-- <origin xyz="0.1025 0 0.015" /> -->
            <origin xyz="0.1025 0 0.025" />
            <geometry>
                <box size="0.205 0.145 0.050" />
            </geometry>
            <material name="black" />
        </visual>
    </link>

    <!-- Left wheel -->
    <joint name="left_wheel_joint" type="continuous">
        <parent link="base_link"/>
        <child link="left_wheel"/>
        <origin xyz="0 0.059 0" rpy="-${pi/2} 0 0" />
        <axis xyz="0 0 1"/>
    </joint>

    <link name="left_wheel">
        <visual>
            <geometry>
                <cylinder radius="0.05" length="0.04"/>
            </geometry>
            <material name="yellow"/>
        </visual>
        <collision>
            <geometry>
                <cylinder radius="0.05" length="0.04"/>
            </geometry>
        </collision>
    </link>

    <!-- <link name="chassis">
        <visual name="bottom_plate">
            <origin xyz="0.0 0.0 0.013" rpy="0.0 0.0 0.0"/>
            <geometry>
                <box size="0.195 0.103 0.005"/>
            </geometry>
            <material name="black">
                <color rgba="0.9 0.9 0.9 1.0"/>
            </material>
        </visual>
        <visual name="top_plate">
            <origin xyz="0.0 0.0 0.060" rpy="0.0 0.0 0.0"/>
            <geometry>
                <box size="0.195 0.103 0.005"/>
            </geometry>
            <material name="black">
                <color rgba="0.7 0.7 0.7 1.0"/>
            </material>
        </visual>
    </link>
    <link name="ultrasone_sensor">
        <visual name="">
            <origin xyz="0.0 0.0 0.0" rpy="0.0 0.0 0.0"/>
            <geometry>
                <box size="0.005 0.043 0.02"/>
            </geometry>
            <material name="blue">
                <color rgba="0.0 1.0 0.0 1.0"/>
                <texture filename=""/>
            </material>
        </visual>
    </link>

	<joint name="SweepSensorServo" type="revolute">
        <origin xyz="0.0765 0.0 0.08" rpy="0.0 0.0 0.0"/>
        <parent link="chassis"/>
        <child link="ultrasone_sensor"/>
        <axis xyz="0 0 1"/>
        <limit lower="-0.785" upper="0.785" effort="0.0" velocity="0.0"/>
    </joint> -->

</robot>