<?xml version="1.0"?>
<robot xmlns:xacro="http://www.ros.org/wiki/xacro">

    <!-- Materials -->
    <material name="white">
        <color rgba="1 1 1 1"/>
    </material>

    <material name="orange">
        <color rgba="1 0.3 0.1 1"/>
    </material>

    <material name="blue">
        <color rgba="0.2 0.2 1 1"/>
    </material>

    <material name="black">
        <color rgba="0 0 0 1"/>
    </material>

    <material name="yellow">
        <color rgba="1 1 0 1"/>
    </material>

    <material name="silver">
        <color rgba="0.7 0.7 0.7 1"/>
    </material>

    <!-- base (in middle of the two wheels) -->
    <link name="base_link">
        <origin xyz="0 0 0.033"/>
    </link>

    <!-- CHASSIS (simplified body of the jvr-robot) -->

    <joint name="chassis_joint" type="fixed">
        <parent link="base_link"/>
        <child link="chassis"/>
        <origin xyz="-0.14 0 -0.015"/>
    </joint>

    <link name="chassis">
        <visual>
            <origin xyz="0.1025 0 0.025"/>
            <geometry>
                <box size="0.205 0.145 0.050"/>
            </geometry>
            <material name="black"/>
        </visual>
        <collision>
            <origin xyz="0.1025 0 0.025"/>
            <geometry>
                <box size="0.205 0.145 0.050"/>
            </geometry>
        </collision>
    </link>

    <!-- Left wheel -->
    <!-- The weels are half inside the box, because the outer edges are used as chassis -->
    <joint name="left_wheel_joint" type="continuous">
        <parent link="base_link"/>
        <child link="left_wheel"/>
        <origin xyz="0 0.072 0" rpy="-${pi/2} 0 0"/>
        <axis xyz="0 0 1"/>
    </joint>

    <link name="left_wheel">
        <visual>
            <geometry>
                <cylinder radius="0.05" length="0.026"/>
            </geometry>
            <material name="yellow"/>
        </visual>
        <collision>
            <geometry>
                <cylinder radius="0.05" length="0.026"/>
            </geometry>
        </collision>
    </link>

    <!-- Right wheel -->
    <!-- The weels are half inside the box, because the outer edges are used as chassis -->
    <joint name="right_wheel_joint" type="continuous">
        <parent link="base_link"/>
        <child link="right_wheel"/>
        <origin xyz="0 -0.072 0" rpy="${pi/2} 0 0"/>
        <axis xyz="0 0 -1"/>
    </joint>

    <link name="right_wheel">
        <visual>
            <geometry>
                <cylinder radius="0.05" length="0.026"/>
            </geometry>
            <material name="yellow"/>
        </visual>
        <collision>
            <geometry>
                <cylinder radius="0.05" length="0.026"/>
            </geometry>
        </collision>
    </link>

    <!-- Caster wheel -->
    <joint name="caster_wheel_joint" type="fixed">
        <parent link="chassis"/>
        <child link="caster_wheel"/>
        <origin xyz="0.016 0 -0.015"/>
    </joint>

    <link name="caster_wheel">
        <visual>
            <geometry>
                <sphere radius="0.008"/>
            </geometry>
            <material name="silver"/>
        </visual>
        <collision>
            <geometry>
                <sphere radius="0.008"/>
            </geometry>
        </collision>
    </link>

    <!-- Sweep sensor -->
    <joint name="sweep_sensor_joint" type="revolute">
        <parent link="chassis"/>
        <child link="sweep_sensor"/>
        <origin xyz="0.187 0 0.059"/>
        <axis xyz="0 0 1"/>
        <!-- lower limit -45deg, upper limit 45deg-->
        <!-- not sure what 'effort' means -->
        <!-- speed 60 deg per 0.3 secs. see https://osoyoo.store/en-eu/products/micro-servo-sg90-blue-for-arduino-v2-0-robot-carmodel-lacc200610#tab_technical-details -->
        <limit lower="-${(pi/180)*45}" upper="${(pi/180)*45}" effort="100.0" velocity="${((pi/180)*60)/0.3}"/>
    </joint>

    <link name="sweep_sensor">
        <visual>
            <origin xyz="0.009 0 0.018"/>
            <geometry>
                <box size="0.002 0.05 0.036"/>
            </geometry>
            <material name="silver"/>
        </visual>
        <visual>
            <origin xyz="0.015 0.01 0.018" rpy="0 ${pi/2} 0"/>
            <geometry>
                <cylinder radius="0.008" length="0.01"/>
            </geometry>
            <material name="silver"/>
        </visual>
        <visual>
            <origin xyz="0.015 -0.01 0.018" rpy="0 ${pi/2} 0"/>
            <geometry>
                <cylinder radius="0.008" length="0.01"/>
            </geometry>
            <material name="silver"/>
        </visual>
        <collision>
            <origin xyz="0.009 0 0.018"/>
            <geometry>
                <box size="0.014 0.05 0.036"/>
            </geometry>
        </collision>
    </link>
</robot>